Workbook
Name Slicer_Country: #N/A
Name Slicer_Flag_Day: #N/A
Name Slicer_Warehouse: #N/A

Sheet Pivot1
A3: Count of Order_ID
A4: 2200 | B4: =GETPIVOTDATA("[Measures].[Count of Order_ID]",$A$3) -> 2200
A6: Sum of Revenue
A7: 2331956.7 | B7: =GETPIVOTDATA("[Measures].[Sum of Revenue]",$A$6) -> 2331956.7
A10: Sum of Net Profit
A11: 778143.22 | B11: =GETPIVOTDATA("[Measures].[Sum of Net Profit]",$A$10) -> 778143.22
A14: Average of Flag_OnTime
A15: 0.81227273 | B15: =GETPIVOTDATA("[Measures].[Average of Flag_OnTime]",$A$14) -> 0.81227273
A18: Average of Lead Time
A19: 2.9922727 | B19: =GETPIVOTDATA("[Measures].[Average of Lead Time]",$A$18) -> 2.9922727
A24: Row Labels | B24: Average of Flag_OnTime
A25: 45658 | B25: 1
A26: 45659 | B26: 1
A27: 45660 | B27: 1
A28: 45661 | B28: 1
A29: 45662 | B29: 1
A30: 45663 | B30: 1
A31: 45664 | B31: 1
A32: 45665 | B32: 1
A33: 45666 | B33: 1
A34: 45667 | B34: 1
A35: 45668 | B35: 1
A36: 45669 | B36: 1
... A55: 45688 | B55: 0.65333333
A56: Grand Total | B56: 0.81227273
A59: Row Labels | B59: Average of Lead Time
A60: 45658 | B60: 2.5441176
A61: 45659 | B61: 2.3384615
A62: 45660 | B62: 2.4318182
A63: 45661 | B63: 2.4383562
A64: 45662 | B64: 2.4444444
A65: 45663 | B65: 2.76
A66: 45664 | B66: 2.6341463
A67: 45665 | B67: 2.4461538
A68: 45666 | B68: 2.7014925
A69: 45667 | B69: 2.3709677
A70: 45668 | B70: 2.557377
A71: 45669 | B71: 2.2698413
... A90: 45688 | B90: 3.48
A91: Grand Total | B91: 2.9922727
...

Sheet Orders_Fact
A1: Order_ID | B1: Order_Date | C1: Promised_Date | D1: Actual_Delivery_Date | E1: Customer_Type | F1: Country | G1: Warehouse | H1: Route_ID | I1: SKU | J1: Category | K1: Sold_Qty | L1: Price_per_Unit | M1: COGS_per_Unit | N1: Logistics_Cost_per_Unit | O1: Discount_% | P1: Flag_OnTime | Q1: Flag_Day | R1: Net Price | S1: Revenue | T1: Gross profit | U1: Other Costs | V1: Logistics costs | W1: Net Profit | X1: Lead Time | Y1: Loss_making Orders
A2: ORD_00001 | B2: 45675 | C2: 45678 | D2: 45677 | E2: B2B | F2: HU | G2: WH_B | H2: R02 | I2: SKU_H1 | J2: Home | K2: 7 | L2: 84.32 | M2: 38.75 | N2: 10.57 | O2: 15 | P2: =IF(D2-C2 <= 0,1,0) -> 1 | Q2: =IF(B2<=DATE(2025,1,15),"Before 01-15","After 01-15") -> After 01-15 | R2: =L2*(1-(0.01*O2)) -> 71.672 | S2: =R2*K2 -> 501.704 | T2: =S2-(M2*K2) -> 230.454 | U2: =Monthly_Fixed_Costs!$I$2 -> 26.363636 | V2: =N2*K2 -> 73.99 | W2: =T2-(U2+V2) -> 130.10036 | X2: =D2-B2 -> 2 | Y2: =IF(W2<10,1,0) -> 0
A3: ORD_00002 | B3: 45687 | C3: 45689 | D3: 45690 | E3: Retail | F3: HU | G3: WH_A | H3: R01 | I3: SKU_O1 | J3: Office | K3: 7 | L3: 105.22 | M3: 58.08 | N3: 9.15 | O3: 5 | P3: =IF(D3-C3 <= 0,1,0) -> 0 | Q3: =IF(B3<=DATE(2025,1,15),"Before 01-15","After 01-15") -> After 01-15 | R3: =L3*(1-(0.01*O3)) -> 99.959 | S3: =R3*K3 -> 699.713 | T3: =S3-(M3*K3) -> 293.153 | U3: =Monthly_Fixed_Costs!$I$2 -> 26.363636 | V3: =N3*K3 -> 64.05 | W3: =T3-(U3+V3) -> 202.73936 | X3: =D3-B3 -> 3 | Y3: =IF(W3<10,1,0) -> 0
A4: ORD_00003 | B4: 45667 | C4: 45671 | D4: 45671 | E4: Retail | F4: HU | G4: WH_B | H4: R02 | I4: SKU_O2 | J4: Office | K4: 4 | L4: 23.58 | M4: 14.61 | N4: 3.33 | O4: 15 | P4: =IF(D4-C4 <= 0,1,0) -> 1 | Q4: =IF(B4<=DATE(2025,1,15),"Before 01-15","After 01-15") -> Before 01-15 | R4: =L4*(1-(0.01*O4)) -> 20.043 | S4: =R4*K4 -> 80.172 | T4: =S4-(M4*K4) -> 21.732 | U4: =Monthly_Fixed_Costs!$I$2 -> 26.363636 | V4: =N4*K4 -> 13.32 | W4: =T4-(U4+V4) -> -17.951636 | X4: =D4-B4 -> 4 | Y4: =IF(W4<10,1,0) -> 1
A5: ORD_00004 | B5: 45671 | C5: 45673 | D5: 45673 | E5: Retail | F5: HU | G5: WH_B | H5: R01 | I5: SKU_H1 | J5: Home | K5: 14 | L5: 38.56 | M5: 16.6 | N5: 8.79 | O5: 15 | P5: =IF(D5-C5 <= 0,1,0) -> 1 | Q5: =IF(B5<=DATE(2025,1,15),"Before 01-15","After 01-15") -> Before 01-15 | R5: =L5*(1-(0.01*O5)) -> 32.776 | S5: =R5*K5 -> 458.864 | T5: =S5-(M5*K5) -> 226.464 | U5: =Monthly_Fixed_Costs!$I$2 -> 26.363636 | V5: =N5*K5 -> 123.06 | W5: =T5-(U5+V5) -> 77.040364 | X5: =D5-B5 -> 2 | Y5: =IF(W5<10,1,0) -> 0
A6: ORD_00005 | B6: 45658 | C6: 45662 | D6: 45662 | E6: B2B | F6: SK | G6: WH_B | H6: R04 | I6: SKU_E3 | J6: Electronics | K6: 14 | L6: 29.67 | M6: 13.73 | N6: 6.91 | O6: 15 | P6: =IF(D6-C6 <= 0,1,0) -> 1 | Q6: =IF(B6<=DATE(2025,1,15),"Before 01-15","After 01-15") -> Before 01-15 | R6: =L6*(1-(0.01*O6)) -> 25.2195 | S6: =R6*K6 -> 353.073 | T6: =S6-(M6*K6) -> 160.853 | U6: =Monthly_Fixed_Costs!$I$2 -> 26.363636 | V6: =N6*K6 -> 96.74 | W6: =T6-(U6+V6) -> 37.749364 | X6: =D6-B6 -> 4 | Y6: =IF(W6<10,1,0) -> 0
A7: ORD_00006 | B7: 45688 | C7: 45691 | D7: 45693 | E7: Retail | F7: HU | G7: WH_A | H7: R03 | I7: SKU_H2 | J7: Home | K7: 11 | L7: 170.24 | M7: 105.51 | N7: 7.42 | O7: 15 | P7: =IF(D7-C7 <= 0,1,0) -> 0 | Q7: =IF(B7<=DATE(2025,1,15),"Before 01-15","After 01-15") -> After 01-15 | R7: =L7*(1-(0.01*O7)) -> 144.704 | S7: =R7*K7 -> 1591.744 | T7: =S7-(M7*K7) -> 431.134 | U7: =Monthly_Fixed_Costs!$I$2 -> 26.363636 | V7: =N7*K7 -> 81.62 | W7: =T7-(U7+V7) -> 323.15036 | X7: =D7-B7 -> 5 | Y7: =IF(W7<10,1,0) -> 0
A8: ORD_00007 | B8: 45661 | C8: 45665 | D8: 45665 | E8: B2B | F8: HU | G8: WH_A | H8: R03 | I8: SKU_E3 | J8: Electronics | K8: 15 | L8: 35.02 | M8: 19.24 | N8: 7.64 | O8: 10 | P8: =IF(D8-C8 <= 0,1,0) -> 1 | Q8: =IF(B8<=DATE(2025,1,15),"Before 01-15","After 01-15") -> Before 01-15 | R8: =L8*(1-(0.01*O8)) -> 31.518 | S8: =R8*K8 -> 472.77 | T8: =S8-(M8*K8) -> 184.17 | U8: =Monthly_Fixed_Costs!$I$2 -> 26.363636 | V8: =N8*K8 -> 114.6 | W8: =T8-(U8+V8) -> 43.206364 | X8: =D8-B8 -> 4 | Y8: =IF(W8<10,1,0) -> 0
A9: ORD_00008 | B9: 45687 | C9: 45690 | D9: 45692 | E9: Retail | F9: CZ | G9: WH_B | H9: R04 | I9: SKU_H2 | J9: Home | K9: 1 | L9: 150.13 | M9: 60.92 | N9: 5.74 | O9: 15 | P9: =IF(D9-C9 <= 0,1,0) -> 0 | Q9: =IF(B9<=DATE(2025,1,15),"Before 01-15","After 01-15") -> After 01-15 | R9: =L9*(1-(0.01*O9)) -> 127.6105 | S9: =R9*K9 -> 127.6105 | T9: =S9-(M9*K9) -> 66.6905 | U9: =Monthly_Fixed_Costs!$I$2 -> 26.363636 | V9: =N9*K9 -> 5.74 | W9: =T9-(U9+V9) -> 34.586864 | X9: =D9-B9 -> 5 | Y9: =IF(W9<10,1,0) -> 0
A10: ORD_00009 | B10: 45676 | C10: 45680 | D10: 45681 | E10: Retail | F10: SK | G10: WH_A | H10: R01 | I10: SKU_H2 | J10: Home | K10: 4 | L10: 30.79 | M10: 12.58 | N10: 7.72 | O10: 0 | P10: =IF(D10-C10 <= 0,1,0) -> 0 | Q10: =IF(B10<=DATE(2025,1,15),"Before 01-15","After 01-15") -> After 01-15 | R10: =L10*(1-(0.01*O10)) -> 30.79 | S10: =R10*K10 -> 123.16 | T10: =S10-(M10*K10) -> 72.84 | U10: =Monthly_Fixed_Costs!$I$2 -> 26.363636 | V10: =N10*K10 -> 30.88 | W10: =T10-(U10+V10) -> 15.596364 | X10: =D10-B10 -> 5 | Y10: =IF(W10<10,1,0) -> 0
A11: ORD_00010 | B11: 45661 | C11: 45663 | D11: 45662 | E11: Retail | F11: HU | G11: WH_B | H11: R03 | I11: SKU_H2 | J11: Home | K11: 4 | L11: 33 | M11: 17.42 | N11: 3.93 | O11: 5 | P11: =IF(D11-C11 <= 0,1,0) -> 1 | Q11: =IF(B11<=DATE(2025,1,15),"Before 01-15","After 01-15") -> Before 01-15 | R11: =L11*(1-(0.01*O11)) -> 31.35 | S11: =R11*K11 -> 125.4 | T11: =S11-(M11*K11) -> 55.72 | U11: =Monthly_Fixed_Costs!$I$2 -> 26.363636 | V11: =N11*K11 -> 15.72 | W11: =T11-(U11+V11) -> 13.636364 | X11: =D11-B11 -> 1 | Y11: =IF(W11<10,1,0) -> 0
A12: ORD_00011 | B12: 45681 | C12: 45683 | D12: 45683 | E12: Retail | F12: PL | G12: WH_B | H12: R02 | I12: SKU_H1 | J12: Home | K12: 13 | L12: 36.04 | M12: 22.08 | N12: 4.91 | O12: 5 | P12: =IF(D12-C12 <= 0,1,0) -> 1 | Q12: =IF(B12<=DATE(2025,1,15),"Before 01-15","After 01-15") -> After 01-15 | R12: =L12*(1-(0.01*O12)) -> 34.238 | S12: =R12*K12 -> 445.094 | T12: =S12-(M12*K12) -> 158.054 | U12: =Monthly_Fixed_Costs!$I$2 -> 26.363636 | V12: =N12*K12 -> 63.83 | W12: =T12-(U12+V12) -> 67.860364 | X12: =D12-B12 -> 2 | Y12: =IF(W12<10,1,0) -> 0
A13: ORD_00012 | B13: 45670 | C13: 45672 | D13: 45671 | E13: B2B | F13: CZ | G13: WH_B | H13: R01 | I13: SKU_E2 | J13: Electronics | K13: 12 | L13: 24.58 | M13: 14.59 | N13: 5.34 | O13: 5 | P13: =IF(D13-C13 <= 0,1,0) -> 1 | Q13: =IF(B13<=DATE(2025,1,15),"Before 01-15","After 01-15") -> Before 01-15 | R13: =L13*(1-(0.01*O13)) -> 23.351 | S13: =R13*K13 -> 280.212 | T13: =S13-(M13*K13) -> 105.132 | U13: =Monthly_Fixed_Costs!$I$2 -> 26.363636 | V13: =N13*K13 -> 64.08 | W13: =T13-(U13+V13) -> 14.688364 | X13: =D13-B13 -> 1 | Y13: =IF(W13<10,1,0) -> 0
... A2201: ORD_02200 | B2201: 45673 | C2201: 45675 | D2201: 45675 | E2201: B2B | F2201: PL | G2201: WH_A | H2201: R03 | I2201: SKU_E1 | J2201: Electronics | K2201: 5 | L2201: 185.21 | M2201: 84.43 | N2201: 8.58 | O2201: 0 | P2201: =IF(D2201-C2201 <= 0,1,0) -> 1 | Q2201: =IF(B2201<=DATE(2025,1,15),"Before 01-15","After 01-15") -> After 01-15 | R2201: =L2201*(1-(0.01*O2201)) -> 185.21 | S2201: =R2201*K2201 -> 926.05 | T2201: =S2201-(M2201*K2201) -> 503.9 | U2201: =Monthly_Fixed_Costs!$I$2 -> 26.363636 | V2201: =N2201*K2201 -> 42.9 | W2201: =T2201-(U2201+V2201) -> 434.63636 | X2201: =D2201-B2201 -> 2 | Y2201: =IF(W2201<10,1,0) -> 0
S1048576: =SUM(S2:S1048575) -> 2331956.7

Sheet Monthly_Fixed_Costs
A1: Year | B1: Month | C1: Cost_Type | D1: Amount | G1: Total costs | H1: Total orders | I1: Cost_per_order
A2: 2025 | B2: 1 | C2: Warehouse Rent | D2: 25000 | G2: =SUM(D2:D5) -> 58000 | H2: =COUNTA(Orders_Fact!A2:A2201) -> 2200 | I2: =G2/H2 -> 26.363636
A3: 2025 | B3: 1 | C3: IT Systems | D3: 6000
A4: 2025 | B4: 1 | C4: Admin Salaries | D4: 18000
A5: 2025 | B5: 1 | C5: Marketing | D5: 9000

Sheet Executive Dashboard
